Workbook

Sheet Instrucciones
B2: PLANTILLA DE VALIDACIÓN DE REQUISITOS
B3: Detección de ambigüedades en User Stories + Criterios de Aceptación BDD (antes de codificar)
B5: Proyecto / Curso: | C5: INGENIERIA DE REQUISITOS
B6: Responsable de validación: | C6: Anthony Joel Romero Yaguana
B7: Fecha: | C7: 10/07/2026
B8: Versión de la plantilla: | C8: 1.0
B9: Marco de referencia: | C9: ISO/IEC/IEEE 29148:2018 · BDD (Given–When–Then) · INVEST
B11: OBJETIVO
B12: Proporcionar un instrumento estructurado para validar la calidad de las user stories, detectar ambigüedades (semánticas, funcionales, temporales y de alcance) y verificar que cada historia cuente con criterios de aceptación BDD verificables ANTES de iniciar la codificación. Con ello se reduce el retrabajo, se mejora la trazabilidad y se alinea el equipo en torno a un lenguaje común (lenguaje ubicuo).
B14: CÓMO USAR ESTA PLANTILLA
B15: 1. Checklist Ambigüedades | C15: Evalúe cada user story frente a los ítems del checklist. Marque el Estado (✓ Cumple / ✗ No cumple / N/A) usando la lista desplegable. Registre hallazgos y la reescritura sugerida.
B16: 2. Guía BDD | C16: Consulte la guía rápida para redactar criterios de aceptación en formato Given–When–Then. Incluye plantilla, ejemplos correctos/incorrectos y una checklist de calidad de escenarios.
B17: 3. Registro de Validación | C17: Consolide el veredicto por historia (Aprobada / Aprobada con observaciones / Rechazada). El tablero calcula automáticamente el estado del backlog.
B18: Regla de oro | C18: Ninguna historia debe pasar a desarrollo (Definition of Ready) sin: (a) cero ambigüedades críticas y (b) al menos un escenario BDD verificable.
B20: LEYENDA DE ESTADOS
B21: ✓ Cumple | C21: El criterio se satisface plenamente.
B22: ✗ No cumple | C22: Se detecta una ambigüedad o deficiencia que debe corregirse.
B23: ⚠ Revisar | C23: Requiere aclaración o depende de otra decisión.
B24: N/A | C24: No aplica a esta historia.

Sheet Guía BDD
B2: GUÍA RÁPIDA — CRITERIOS DE ACEPTACIÓN BDD
B3: Behavior-Driven Development · Estructura Given–When–Then (Dado–Cuando–Entonces)
B5: 1. ESTRUCTURA (Gherkin)
B6: Given (Dado) | C6: Contexto / precondición: el estado del sistema antes de la acción.
B7: When (Cuando) | C7: El evento o acción que dispara el comportamiento a validar.
B8: Then (Entonces) | C8: El resultado observable y verificable que debe cumplirse.
B9: And / But (Y / Pero) | C9: Encadena condiciones o resultados adicionales dentro de cualquier bloque.
B11: 2. PLANTILLA REUTILIZABLE
B12: Escenario: <título breve y descriptivo del comportamiento> Dado <precondición / contexto inicial> Y <precondición adicional, si aplica> Cuando <acción o evento que ejecuta el usuario/sistema> Entonces <resultado esperado, observable y medible> Y <resultado adicional / efecto secundario verificable>
B20: 3. EJEMPLO: DE AMBIGUO A VERIFICABLE
B21: User Story | C21: ✗ Criterio ambiguo (mal) | D21: ✓ Criterio BDD verificable (bien)
B22: Como cliente, quiero recuperar mi contraseña para volver a ingresar a mi cuenta. | C22: El sistema debe permitir recuperar la contraseña de forma rápida y sencilla. (No define disparador, tiempo, ni resultado verificable.) | D22: Escenario: Recuperación con correo registrado Dado que el cliente tiene una cuenta con el correo 'ana@mail.com' Cuando solicita recuperar su contraseña con ese correo Entonces el sistema envía un enlace de restablecimiento en menos de 60 segundos Y el enlace expira a los 15 minutos Escenario: Correo no registrado Dado que el correo 'x@mail.com' no existe Cuando el cliente solicita recuperación Entonces se muestra 'Si el correo existe, enviaremos instrucciones' sin revelar si está registrado
B24: 4. CHECKLIST DE CALIDAD DEL ESCENARIO (antes de codificar)
B25: OK | C25: Criterio de calidad
B26: ☐ | C26: Cada escenario valida UN solo comportamiento (atómico).
B27: ☐ | C27: El resultado en 'Entonces' es observable y medible (sin ambigüedad).
B28: ☐ | C28: Se cubre al menos un camino feliz y un camino alterno/negativo.
B29: ☐ | C29: No hay detalles de implementación (describe QUÉ, no CÓMO).
B30: ☐ | C30: Usa el lenguaje ubicuo del dominio (términos del glosario).
B31: ☐ | C31: Los datos de ejemplo son concretos (valores reales, no 'algún dato').
B32: ☐ | C32: Es independiente: no depende del orden de ejecución de otros escenarios.
B33: ☐ | C33: Es automatizable (se puede traducir a una prueba).
B34: ☐ | C34: Cubre precondiciones de tiempo/estado cuando aplica (temporalidad).
B35: ☐ | C35: El alcance del escenario coincide con el de la user story (sin desbordarse).

Sheet CHK-US-001
B2: CHECKLIST DE DETECCIÓN DE AMBIGÜEDADES EN USER STORIES
B3: ID de la User Story: | D3: US-001 | E3: Evaluador: | G3: Anthony Joel Romero Yaguana
B4: Historia (Como <rol>, quiero <objetivo>, para <beneficio>):
B5: Como Analista de Triaje, quiero registrar un nuevo caso de Apelación, Queja o Reclamación consolidando automáticamente los datos disponibles, para iniciar su gestión con información completa desde el primer momento.
B7: # | C7: Aspecto a verificar | D7: Pregunta guía / criterio | E7: Estado | F7: Hallazgo detectado | G7: Reescritura sugerida
B8: AMBIGÜEDAD SEMÁNTICA
B9: 1 | C9: Términos vagos / subjetivos | D9: ¿Se evitan palabras como 'rápido', 'fácil', 'amigable', 'eficiente', 'intuitivo', 'óptimo' sin métrica? | E9: ✓ Cumple
B10: 2 | C10: Lenguaje ubicuo | D10: ¿Los términos del dominio están definidos en un glosario y se usan de forma consistente? | E10: ⚠ Revisar | F10: No se anexa un glosario formal de términos del dominio (caso, triaje, SLA, clasificación, confiabilidad, etc.); los términos se usan de forma consistente pero sin definición central. | G10: Anexar/referenciar un glosario de dominio compartido por todas las historias del backlog.
B11: 3 | C11: Sinónimos / homónimos | D11: ¿Un mismo concepto se nombra siempre igual? ¿Un término no tiene dos significados? | E11: ✓ Cumple
B12: 4 | C12: Pronombres sin referente | D12: ¿Se evita 'esto', 'eso', 'lo anterior' sin un sujeto claro? | E12: ✓ Cumple
B13: 5 | C13: Adjetivos cuantificables | D13: ¿Los calificativos ('grande', 'muchos', 'suficiente') se expresan con números o rangos? | E13: ✓ Cumple
B14: AMBIGÜEDAD FUNCIONAL
B15: 6 | C15: Acción única y clara | D15: ¿La historia describe una sola capacidad? ¿Se evita el 'y/o' que oculta múltiples funciones? | E15: ✓ Cumple
B16: 7 | C16: Actor identificado | D16: ¿Está claro QUIÉN ejecuta la acción y quién se beneficia? | E16: ✓ Cumple
B17: 8 | C17: Comportamiento esperado | D17: ¿Se especifica el resultado observable de la acción (no solo la intención)? | E17: ✓ Cumple
B18: 9 | C18: Manejo de errores / excepciones | D18: ¿Se describen los caminos alternos y qué ocurre ante entradas inválidas? | E18: ✓ Cumple
B19: 10 | C19: Reglas de negocio explícitas | D19: ¿Las validaciones, cálculos y condiciones están declaradas y no supuestas? | E19: ✓ Cumple
B20: 11 | C20: Dependencias funcionales | D20: ¿Se identifican precondiciones o historias de las que depende? | E20: ✓ Cumple
B21: AMBIGÜEDAD TEMPORAL
B22: 12 | C22: Momento / disparador | D22: ¿Está claro CUÁNDO ocurre la acción (evento, condición o frecuencia)? | E22: ✓ Cumple
B23: 13 | C23: Orden y secuencia | D23: ¿Se define el orden de los pasos cuando importa la secuencia? | E23: ✓ Cumple
B24: 14 | C24: Plazos y tiempos de respuesta | D24: ¿Se cuantifican tiempos, timeouts, SLA o vigencias ('en X segundos', 'hasta las 23:59')? | E24: N/A
B25: 15 | C25: Estados y transiciones | D25: ¿Se describen los estados del objeto y las transiciones válidas entre ellos? | E25: N/A
B26: 16 | C26: Concurrencia / simultaneidad | D26: ¿Se contempla qué pasa si varios usuarios/procesos actúan a la vez? | E26: ⚠ Revisar | F26: No se contempla qué ocurre si dos analistas registran simultáneamente casos que resultarán duplicados. | G26: Agregar: 'Dado que dos analistas registran casos simultáneamente que resultan duplicados, entonces el sistema aplica la detección de duplicados de US-007 sobre ambos.'
B27: AMBIGÜEDAD DE ALCANCE
B28: 17 | C28: Límites (in/out of scope) | D28: ¿Se declara explícitamente qué queda FUERA del alcance de la historia? | E28: ⚠ Revisar | F28: La historia no declara explícitamente qué queda fuera de su alcance. | G28: Agregar una sección 'Fuera de alcance' que indique explícitamente las funcionalidades excluidas.
B29: 18 | C29: Tamaño / granularidad (INVEST) | D29: ¿La historia es lo bastante pequeña para completarse en un sprint? ¿Es divisible? | E29: ✓ Cumple
B30: 19 | C30: Datos y volúmenes | D30: ¿Se acotan cantidades, límites de registros, formatos y rangos de datos? | E30: N/A
B31: 20 | C31: Roles y permisos afectados | D31: ¿Se delimita a qué perfiles/roles aplica y a cuáles no? | E31: ✓ Cumple
B32: 21 | C32: Plataformas / entornos | D32: ¿Se especifican dispositivos, navegadores, idiomas o entornos cubiertos? | E32: ⚠ Revisar | F32: No se especifican dispositivos, navegadores, resoluciones o idiomas soportados para esta funcionalidad. | G32: Definir explícitamente los entornos soportados (navegador de escritorio, resolución mínima, idioma único: español).
B33: 22 | C33: Criterios medibles / testables | D33: ¿Cada afirmación puede verificarse objetivamente con una prueba? | E33: ✓ Cumple
B35: Ítems 'No cumple' (críticos): | D35: =COUNTIF(E8:E33,"✗ No cumple") -> 0
B36: Ítems 'Revisar': | D36: =COUNTIF(E8:E33,"⚠ Revisar") -> 4
B37: VEREDICTO (Definition of Ready): | D37: =IF(D35>0,"RECHAZADA - corregir ambigüedades críticas",IF(D36>0,"APROBADA CON OBSERVACIONES - aclarar pendientes","APROBADA - lista para BDD")) -> APROBADA CON OBSERVACIONES - aclarar pendientes

Sheet CHK-US-002
B2: CHECKLIST DE DETECCIÓN DE AMBIGÜEDADES EN USER STORIES
B3: ID de la User Story: | D3: US-002 | E3: Evaluador: | G3: Anthony Joel Romero Yaguana
B4: Historia (Como <rol>, quiero <objetivo>, para <beneficio>):
B5: Como Analista de Triaje, quiero localizar y filtrar los casos A&G según mis permisos, para ubicar rápidamente el caso que necesito atender.
B7: # | C7: Aspecto a verificar | D7: Pregunta guía / criterio | E7: Estado | F7: Hallazgo detectado | G7: Reescritura sugerida
B8: AMBIGÜEDAD SEMÁNTICA
B9: 1 | C9: Términos vagos / subjetivos | D9: ¿Se evitan palabras como 'rápido', 'fácil', 'amigable', 'eficiente', 'intuitivo', 'óptimo' sin métrica? | E9: ⚠ Revisar | F9: El beneficio de la historia usa 'rápidamente' sin métrica ('para ubicar rápidamente el caso'). | G9: Reemplazar por: 'para ubicar el caso en menos de 5 segundos desde la aplicación del filtro o búsqueda'.
B10: 2 | C10: Lenguaje ubicuo | D10: ¿Los términos del dominio están definidos en un glosario y se usan de forma consistente? | E10: ⚠ Revisar | F10: No se anexa un glosario formal de términos del dominio (caso, triaje, SLA, clasificación, confiabilidad, etc.); los términos se usan de forma consistente pero sin definición central. | G10: Anexar/referenciar un glosario de dominio compartido por todas las historias del backlog.
B11: 3 | C11: Sinónimos / homónimos | D11: ¿Un mismo concepto se nombra siempre igual? ¿Un término no tiene dos significados? | E11: ✓ Cumple
B12: 4 | C12: Pronombres sin referente | D12: ¿Se evita 'esto', 'eso', 'lo anterior' sin un sujeto claro? | E12: ✓ Cumple
B13: 5 | C13: Adjetivos cuantificables | D13: ¿Los calificativos ('grande', 'muchos', 'suficiente') se expresan con números o rangos? | E13: ✓ Cumple
B14: AMBIGÜEDAD FUNCIONAL
B15: 6 | C15: Acción única y clara | D15: ¿La historia describe una sola capacidad? ¿Se evita el 'y/o' que oculta múltiples funciones? | E15: ✓ Cumple
B16: 7 | C16: Actor identificado | D16: ¿Está claro QUIÉN ejecuta la acción y quién se beneficia? | E16: ✓ Cumple
B17: 8 | C17: Comportamiento esperado | D17: ¿Se especifica el resultado observable de la acción (no solo la intención)? | E17: ✓ Cumple
B18: 9 | C18: Manejo de errores / excepciones | D18: ¿Se describen los caminos alternos y qué ocurre ante entradas inválidas? | E18: ✓ Cumple
B19: 10 | C19: Reglas de negocio explícitas | D19: ¿Las validaciones, cálculos y condiciones están declaradas y no supuestas? | E19: ✓ Cumple
B20: 11 | C20: Dependencias funcionales | D20: ¿Se identifican precondiciones o historias de las que depende? | E20: ✓ Cumple
B21: AMBIGÜEDAD TEMPORAL
B22: 12 | C22: Momento / disparador | D22: ¿Está claro CUÁNDO ocurre la acción (evento, condición o frecuencia)? | E22: ✓ Cumple
B23: 13 | C23: Orden y secuencia | D23: ¿Se define el orden de los pasos cuando importa la secuencia? | E23: ✓ Cumple
B24: 14 | C24: Plazos y tiempos de respuesta | D24: ¿Se cuantifican tiempos, timeouts, SLA o vigencias ('en X segundos', 'hasta las 23:59')? | E24: ⚠ Revisar | F24: No se define un tiempo máximo de respuesta para la búsqueda o el filtrado de casos. | G24: Agregar: 'Entonces el sistema muestra los resultados en menos de X segundos.'
B25: 15 | C25: Estados y transiciones | D25: ¿Se describen los estados del objeto y las transiciones válidas entre ellos? | E25: N/A
B26: 16 | C26: Concurrencia / simultaneidad | D26: ¿Se contempla qué pasa si varios usuarios/procesos actúan a la vez? | E26: N/A
B27: AMBIGÜEDAD DE ALCANCE
B28: 17 | C28: Límites (in/out of scope) | D28: ¿Se declara explícitamente qué queda FUERA del alcance de la historia? | E28: ⚠ Revisar | F28: La historia no declara explícitamente qué queda fuera de su alcance. | G28: Agregar una sección 'Fuera de alcance' que indique explícitamente las funcionalidades excluidas.
B29: 18 | C29: Tamaño / granularidad (INVEST) | D29: ¿La historia es lo bastante pequeña para completarse en un sprint? ¿Es divisible? | E29: ✓ Cumple
B30: 19 | C30: Datos y volúmenes | D30: ¿Se acotan cantidades, límites de registros, formatos y rangos de datos? | E30: ⚠ Revisar | F30: No se acota el número máximo de resultados mostrados ni el comportamiento de paginación. | G30: Definir: 'El listado se pagina de X en X registros' o límite equivalente.
B31: 20 | C31: Roles y permisos afectados | D31: ¿Se delimita a qué perfiles/roles aplica y a cuáles no? | E31: ✓ Cumple
B32: 21 | C32: Plataformas / entornos | D32: ¿Se especifican dispositivos, navegadores, idiomas o entornos cubiertos? | E32: ⚠ Revisar | F32: No se especifican dispositivos, navegadores, resoluciones o idiomas soportados para esta funcionalidad. | G32: Definir explícitamente los entornos soportados (navegador de escritorio, resolución mínima, idioma único: español).
B33: 22 | C33: Criterios medibles / testables | D33: ¿Cada afirmación puede verificarse objetivamente con una prueba? | E33: ✓ Cumple
B35: Ítems 'No cumple' (críticos): | D35: =COUNTIF(E8:E33,"✗ No cumple") -> 0
B36: Ítems 'Revisar': | D36: =COUNTIF(E8:E33,"⚠ Revisar") -> 6
B37: VEREDICTO (Definition of Ready): | D37: =IF(D35>0,"RECHAZADA - corregir ambigüedades críticas",IF(D36>0,"APROBADA CON OBSERVACIONES - aclarar pendientes","APROBADA - lista para BDD")) -> APROBADA CON OBSERVACIONES - aclarar pendientes

Sheet CHK-US-003
B2: CHECKLIST DE DETECCIÓN DE AMBIGÜEDADES EN USER STORIES
B3: ID de la User Story: | D3: US-003 | E3: Evaluador: | G3: Anthony Joel Romero Yaguana
B4: Historia (Como <rol>, quiero <objetivo>, para <beneficio>):
B5: Como Analista de Triaje, quiero actualizar o corregir la información de un caso en estado editable, para mantener los datos precisos durante su gestión.
B7: # | C7: Aspecto a verificar | D7: Pregunta guía / criterio | E7: Estado | F7: Hallazgo detectado | G7: Reescritura sugerida
B8: AMBIGÜEDAD SEMÁNTICA
B9: 1 | C9: Términos vagos / subjetivos | D9: ¿Se evitan palabras como 'rápido', 'fácil', 'amigable', 'eficiente', 'intuitivo', 'óptimo' sin métrica? | E9: ✓ Cumple
B10: 2 | C10: Lenguaje ubicuo | D10: ¿Los términos del dominio están definidos en un glosario y se usan de forma consistente? | E10: ⚠ Revisar | F10: No se anexa un glosario formal de términos del dominio (caso, triaje, SLA, clasificación, confiabilidad, etc.); los términos se usan de forma consistente pero sin definición central. | G10: Anexar/referenciar un glosario de dominio compartido por todas las historias del backlog.
B11: 3 | C11: Sinónimos / homónimos | D11: ¿Un mismo concepto se nombra siempre igual? ¿Un término no tiene dos significados? | E11: ✓ Cumple
B12: 4 | C12: Pronombres sin referente | D12: ¿Se evita 'esto', 'eso', 'lo anterior' sin un sujeto claro? | E12: ✓ Cumple
B13: 5 | C13: Adjetivos cuantificables | D13: ¿Los calificativos ('grande', 'muchos', 'suficiente') se expresan con números o rangos? | E13: ✓ Cumple
B14: AMBIGÜEDAD FUNCIONAL
B15: 6 | C15: Acción única y clara | D15: ¿La historia describe una sola capacidad? ¿Se evita el 'y/o' que oculta múltiples funciones? | E15: ✓ Cumple
B16: 7 | C16: Actor identificado | D16: ¿Está claro QUIÉN ejecuta la acción y quién se beneficia? | E16: ✓ Cumple
B17: 8 | C17: Comportamiento esperado | D17: ¿Se especifica el resultado observable de la acción (no solo la intención)? | E17: ✓ Cumple
B18: 9 | C18: Manejo de errores / excepciones | D18: ¿Se describen los caminos alternos y qué ocurre ante entradas inválidas? | E18: ✓ Cumple
B19: 10 | C19: Reglas de negocio explícitas | D19: ¿Las validaciones, cálculos y condiciones están declaradas y no supuestas? | E19: ✓ Cumple
B20: 11 | C20: Dependencias funcionales | D20: ¿Se identifican precondiciones o historias de las que depende? | E20: ✓ Cumple
B21: AMBIGÜEDAD TEMPORAL
B22: 12 | C22: Momento / disparador | D22: ¿Está claro CUÁNDO ocurre la acción (evento, condición o frecuencia)? | E22: ✓ Cumple
B23: 13 | C23: Orden y secuencia | D23: ¿Se define el orden de los pasos cuando importa la secuencia? | E23: ✓ Cumple
B24: 14 | C24: Plazos y tiempos de respuesta | D24: ¿Se cuantifican tiempos, timeouts, SLA o vigencias ('en X segundos', 'hasta las 23:59')? | E24: N/A
B25: 15 | C25: Estados y transiciones | D25: ¿Se describen los estados del objeto y las transiciones válidas entre ellos? | E25: ✓ Cumple
B26: 16 | C26: Concurrencia / simultaneidad | D26: ¿Se contempla qué pasa si varios usuarios/procesos actúan a la vez? | E26: ⚠ Revisar | F26: No se define qué ocurre si dos usuarios intentan editar el mismo caso simultáneamente. | G26: Agregar: 'Dado que dos usuarios editan el mismo caso a la vez, entonces el sistema aplica bloqueo optimista/pesimista y notifica el conflicto.'
B27: AMBIGÜEDAD DE ALCANCE
B28: 17 | C28: Límites (in/out of scope) | D28: ¿Se declara explícitamente qué queda FUERA del alcance de la historia? | E28: ⚠ Revisar | F28: La historia no declara explícitamente qué queda fuera de su alcance. | G28: Agregar una sección 'Fuera de alcance' que indique explícitamente las funcionalidades excluidas.
B29: 18 | C29: Tamaño / granularidad (INVEST) | D29: ¿La historia es lo bastante pequeña para completarse en un sprint? ¿Es divisible? | E29: ✓ Cumple
B30: 19 | C30: Datos y volúmenes | D30: ¿Se acotan cantidades, límites de registros, formatos y rangos de datos? | E30: N/A
B31: 20 | C31: Roles y permisos afectados | D31: ¿Se delimita a qué perfiles/roles aplica y a cuáles no? | E31: ✓ Cumple
B32: 21 | C32: Plataformas / entornos | D32: ¿Se especifican dispositivos, navegadores, idiomas o entornos cubiertos? | E32: ⚠ Revisar | F32: No se especifican dispositivos, navegadores, resoluciones o idiomas soportados para esta funcionalidad. | G32: Definir explícitamente los entornos soportados (navegador de escritorio, resolución mínima, idioma único: español).
B33: 22 | C33: Criterios medibles / testables | D33: ¿Cada afirmación puede verificarse objetivamente con una prueba? | E33: ✓ Cumple
B35: Ítems 'No cumple' (críticos): | D35: =COUNTIF(E8:E33,"✗ No cumple") -> 0
B36: Ítems 'Revisar': | D36: =COUNTIF(E8:E33,"⚠ Revisar") -> 4
B37: VEREDICTO (Definition of Ready): | D37: =IF(D35>0,"RECHAZADA - corregir ambigüedades críticas",IF(D36>0,"APROBADA CON OBSERVACIONES - aclarar pendientes","APROBADA - lista para BDD")) -> APROBADA CON OBSERVACIONES - aclarar pendientes

Sheet CHK-US-004
B2: CHECKLIST DE DETECCIÓN DE AMBIGÜEDADES EN USER STORIES
B3: ID de la User Story: | D3: US-004 | E3: Evaluador: | G3: Anthony Joel Romero Yaguana
B4: Historia (Como <rol>, quiero <objetivo>, para <beneficio>):
B5: Como Analista de Triaje, quiero que el sistema clasifique automáticamente el caso registrado asignando categoría, subcategoría, prioridad y nivel de confiabilidad, para agilizar la categorización inicial sin depender únicamente del criterio manual.
B7: # | C7: Aspecto a verificar | D7: Pregunta guía / criterio | E7: Estado | F7: Hallazgo detectado | G7: Reescritura sugerida
B8: AMBIGÜEDAD SEMÁNTICA
B9: 1 | C9: Términos vagos / subjetivos | D9: ¿Se evitan palabras como 'rápido', 'fácil', 'amigable', 'eficiente', 'intuitivo', 'óptimo' sin métrica? | E9: ✓ Cumple
B10: 2 | C10: Lenguaje ubicuo | D10: ¿Los términos del dominio están definidos en un glosario y se usan de forma consistente? | E10: ⚠ Revisar | F10: No se anexa un glosario formal de términos del dominio (caso, triaje, SLA, clasificación, confiabilidad, etc.); los términos se usan de forma consistente pero sin definición central. | G10: Anexar/referenciar un glosario de dominio compartido por todas las historias del backlog.
B11: 3 | C11: Sinónimos / homónimos | D11: ¿Un mismo concepto se nombra siempre igual? ¿Un término no tiene dos significados? | E11: ✓ Cumple
B12: 4 | C12: Pronombres sin referente | D12: ¿Se evita 'esto', 'eso', 'lo anterior' sin un sujeto claro? | E12: ✓ Cumple
B13: 5 | C13: Adjetivos cuantificables | D13: ¿Los calificativos ('grande', 'muchos', 'suficiente') se expresan con números o rangos? | E13: ✓ Cumple
B14: AMBIGÜEDAD FUNCIONAL
B15: 6 | C15: Acción única y clara | D15: ¿La historia describe una sola capacidad? ¿Se evita el 'y/o' que oculta múltiples funciones? | E15: ✓ Cumple
B16: 7 | C16: Actor identificado | D16: ¿Está claro QUIÉN ejecuta la acción y quién se beneficia? | E16: ✓ Cumple
B17: 8 | C17: Comportamiento esperado | D17: ¿Se especifica el resultado observable de la acción (no solo la intención)? | E17: ✓ Cumple
B18: 9 | C18: Manejo de errores / excepciones | D18: ¿Se describen los caminos alternos y qué ocurre ante entradas inválidas? | E18: ✓ Cumple
B19: 10 | C19: Reglas de negocio explícitas | D19: ¿Las validaciones, cálculos y condiciones están declaradas y no supuestas? | E19: ✓ Cumple
B20: 11 | C20: Dependencias funcionales | D20: ¿Se identifican precondiciones o historias de las que depende? | E20: ✓ Cumple
B21: AMBIGÜEDAD TEMPORAL
B22: 12 | C22: Momento / disparador | D22: ¿Está claro CUÁNDO ocurre la acción (evento, condición o frecuencia)? | E22: ✓ Cumple
B23: 13 | C23: Orden y secuencia | D23: ¿Se define el orden de los pasos cuando importa la secuencia? | E23: ✓ Cumple
B24: 14 | C24: Plazos y tiempos de respuesta | D24: ¿Se cuantifican tiempos, timeouts, SLA o vigencias ('en X segundos', 'hasta las 23:59')? | E24: ⚠ Revisar | F24: No se define un tiempo máximo para que el motor de clasificación procese el caso. | G24: Agregar un SLA de procesamiento, por ejemplo: 'en menos de X segundos'.
B25: 15 | C25: Estados y transiciones | D25: ¿Se describen los estados del objeto y las transiciones válidas entre ellos? | E25: ✓ Cumple
B26: 16 | C26: Concurrencia / simultaneidad | D26: ¿Se contempla qué pasa si varios usuarios/procesos actúan a la vez? | E26: ⚠ Revisar | F26: No se contempla la clasificación concurrente de múltiples casos ni el orden de prioridad de procesamiento. | G26: Aclarar el comportamiento del motor ante picos de carga simultánea.
B27: AMBIGÜEDAD DE ALCANCE
B28: 17 | C28: Límites (in/out of scope) | D28: ¿Se declara explícitamente qué queda FUERA del alcance de la historia? | E28: ⚠ Revisar | F28: La historia no declara explícitamente qué queda fuera de su alcance. | G28: Agregar una sección 'Fuera de alcance' que indique explícitamente las funcionalidades excluidas.
B29: 18 | C29: Tamaño / granularidad (INVEST) | D29: ¿La historia es lo bastante pequeña para completarse en un sprint? ¿Es divisible? | E29: ⚠ Revisar | F29: Estimación de 8 puntos: evaluar si la historia es divisible (p. ej. separar 'motor de reglas' de 'motor NLP'). | G29: Considerar dividir en dos historias más pequeñas si el sprint no lo permite completar.
B30: 19 | C30: Datos y volúmenes | D30: ¿Se acotan cantidades, límites de registros, formatos y rangos de datos? | E30: ⚠ Revisar | F30: El umbral de confiabilidad se abstrajo a 'umbral configurado'; el valor concreto (0.75) solo aparece en la Épica EP-02. | G30: Referenciar explícitamente el valor o el documento de configuración (EP-02) desde la propia historia.
B31: 20 | C31: Roles y permisos afectados | D31: ¿Se delimita a qué perfiles/roles aplica y a cuáles no? | E31: ✓ Cumple
B32: 21 | C32: Plataformas / entornos | D32: ¿Se especifican dispositivos, navegadores, idiomas o entornos cubiertos? | E32: ⚠ Revisar | F32: No se especifican dispositivos, navegadores, resoluciones o idiomas soportados para esta funcionalidad. | G32: Definir explícitamente los entornos soportados (navegador de escritorio, resolución mínima, idioma único: español).
B33: 22 | C33: Criterios medibles / testables | D33: ¿Cada afirmación puede verificarse objetivamente con una prueba? | E33: ✓ Cumple
B35: Ítems 'No cumple' (críticos): | D35: =COUNTIF(E8:E33,"✗ No cumple") -> 0
B36: Ítems 'Revisar': | D36: =COUNTIF(E8:E33,"⚠ Revisar") -> 7
B37: VEREDICTO (Definition of Ready): | D37: =IF(D35>0,"RECHAZADA - corregir ambigüedades críticas",IF(D36>0,"APROBADA CON OBSERVACIONES - aclarar pendientes","APROBADA - lista para BDD")) -> APROBADA CON OBSERVACIONES - aclarar pendientes

Sheet CHK-US-005
B2: CHECKLIST DE DETECCIÓN DE AMBIGÜEDADES EN USER STORIES
B3: ID de la User Story: | D3: US-005 | E3: Evaluador: | G3: Anthony Joel Romero Yaguana
B4: Historia (Como <rol>, quiero <objetivo>, para <beneficio>):
B5: Como Analista de Triaje, quiero validar o corregir la clasificación automática del caso, para asegurar que la categorización final sea correcta antes de continuar con el proceso.
B7: # | C7: Aspecto a verificar | D7: Pregunta guía / criterio | E7: Estado | F7: Hallazgo detectado | G7: Reescritura sugerida
B8: AMBIGÜEDAD SEMÁNTICA
B9: 1 | C9: Términos vagos / subjetivos | D9: ¿Se evitan palabras como 'rápido', 'fácil', 'amigable', 'eficiente', 'intuitivo', 'óptimo' sin métrica? | E9: ✓ Cumple
B10: 2 | C10: Lenguaje ubicuo | D10: ¿Los términos del dominio están definidos en un glosario y se usan de forma consistente? | E10: ⚠ Revisar | F10: No se anexa un glosario formal de términos del dominio (caso, triaje, SLA, clasificación, confiabilidad, etc.); los términos se usan de forma consistente pero sin definición central. | G10: Anexar/referenciar un glosario de dominio compartido por todas las historias del backlog.
B11: 3 | C11: Sinónimos / homónimos | D11: ¿Un mismo concepto se nombra siempre igual? ¿Un término no tiene dos significados? | E11: ✓ Cumple
B12: 4 | C12: Pronombres sin referente | D12: ¿Se evita 'esto', 'eso', 'lo anterior' sin un sujeto claro? | E12: ✓ Cumple
B13: 5 | C13: Adjetivos cuantificables | D13: ¿Los calificativos ('grande', 'muchos', 'suficiente') se expresan con números o rangos? | E13: ✓ Cumple
B14: AMBIGÜEDAD FUNCIONAL
B15: 6 | C15: Acción única y clara | D15: ¿La historia describe una sola capacidad? ¿Se evita el 'y/o' que oculta múltiples funciones? | E15: ✓ Cumple
B16: 7 | C16: Actor identificado | D16: ¿Está claro QUIÉN ejecuta la acción y quién se beneficia? | E16: ✓ Cumple
B17: 8 | C17: Comportamiento esperado | D17: ¿Se especifica el resultado observable de la acción (no solo la intención)? | E17: ✓ Cumple
B18: 9 | C18: Manejo de errores / excepciones | D18: ¿Se describen los caminos alternos y qué ocurre ante entradas inválidas? | E18: ✓ Cumple
B19: 10 | C19: Reglas de negocio explícitas | D19: ¿Las validaciones, cálculos y condiciones están declaradas y no supuestas? | E19: ✓ Cumple
B20: 11 | C20: Dependencias funcionales | D20: ¿Se identifican precondiciones o historias de las que depende? | E20: ✓ Cumple
B21: AMBIGÜEDAD TEMPORAL
B22: 12 | C22: Momento / disparador | D22: ¿Está claro CUÁNDO ocurre la acción (evento, condición o frecuencia)? | E22: ✓ Cumple
B23: 13 | C23: Orden y secuencia | D23: ¿Se define el orden de los pasos cuando importa la secuencia? | E23: ✓ Cumple
B24: 14 | C24: Plazos y tiempos de respuesta | D24: ¿Se cuantifican tiempos, timeouts, SLA o vigencias ('en X segundos', 'hasta las 23:59')? | E24: N/A
B25: 15 | C25: Estados y transiciones | D25: ¿Se describen los estados del objeto y las transiciones válidas entre ellos? | E25: ✓ Cumple
B26: 16 | C26: Concurrencia / simultaneidad | D26: ¿Se contempla qué pasa si varios usuarios/procesos actúan a la vez? | E26: N/A
B27: AMBIGÜEDAD DE ALCANCE
B28: 17 | C28: Límites (in/out of scope) | D28: ¿Se declara explícitamente qué queda FUERA del alcance de la historia? | E28: ⚠ Revisar | F28: La historia no declara explícitamente qué queda fuera de su alcance. | G28: Agregar una sección 'Fuera de alcance' que indique explícitamente las funcionalidades excluidas.
B29: 18 | C29: Tamaño / granularidad (INVEST) | D29: ¿La historia es lo bastante pequeña para completarse en un sprint? ¿Es divisible? | E29: ✓ Cumple
B30: 19 | C30: Datos y volúmenes | D30: ¿Se acotan cantidades, límites de registros, formatos y rangos de datos? | E30: N/A
B31: 20 | C31: Roles y permisos afectados | D31: ¿Se delimita a qué perfiles/roles aplica y a cuáles no? | E31: ✓ Cumple
B32: 21 | C32: Plataformas / entornos | D32: ¿Se especifican dispositivos, navegadores, idiomas o entornos cubiertos? | E32: ⚠ Revisar | F32: No se especifican dispositivos, navegadores, resoluciones o idiomas soportados para esta funcionalidad. | G32: Definir explícitamente los entornos soportados (navegador de escritorio, resolución mínima, idioma único: español).
B33: 22 | C33: Criterios medibles / testables | D33: ¿Cada afirmación puede verificarse objetivamente con una prueba? | E33: ✓ Cumple
B35: Ítems 'No cumple' (críticos): | D35: =COUNTIF(E8:E33,"✗ No cumple") -> 0
B36: Ítems 'Revisar': | D36: =COUNTIF(E8:E33,"⚠ Revisar") -> 3
B37: VEREDICTO (Definition of Ready): | D37: =IF(D35>0,"RECHAZADA - corregir ambigüedades críticas",IF(D36>0,"APROBADA CON OBSERVACIONES - aclarar pendientes","APROBADA - lista para BDD")) -> APROBADA CON OBSERVACIONES - aclarar pendientes

Sheet CHK-US-006
B2: CHECKLIST DE DETECCIÓN DE AMBIGÜEDADES EN USER STORIES
B3: ID de la User Story: | D3: US-006 | E3: Evaluador: | G3: Anthony Joel Romero Yaguana
B4: Historia (Como <rol>, quiero <objetivo>, para <beneficio>):
B5: Como Analista de Triaje, quiero registrar de forma auditable el fundamento de mis decisiones de triaje, para sostener la trazabilidad exigida en auditorías regulatorias.
B7: # | C7: Aspecto a verificar | D7: Pregunta guía / criterio | E7: Estado | F7: Hallazgo detectado | G7: Reescritura sugerida
B8: AMBIGÜEDAD SEMÁNTICA
B9: 1 | C9: Términos vagos / subjetivos | D9: ¿Se evitan palabras como 'rápido', 'fácil', 'amigable', 'eficiente', 'intuitivo', 'óptimo' sin métrica? | E9: ✓ Cumple
B10: 2 | C10: Lenguaje ubicuo | D10: ¿Los términos del dominio están definidos en un glosario y se usan de forma consistente? | E10: ⚠ Revisar | F10: No se anexa un glosario formal de términos del dominio (caso, triaje, SLA, clasificación, confiabilidad, etc.); los términos se usan de forma consistente pero sin definición central. | G10: Anexar/referenciar un glosario de dominio compartido por todas las historias del backlog.
B11: 3 | C11: Sinónimos / homónimos | D11: ¿Un mismo concepto se nombra siempre igual? ¿Un término no tiene dos significados? | E11: ✓ Cumple
B12: 4 | C12: Pronombres sin referente | D12: ¿Se evita 'esto', 'eso', 'lo anterior' sin un sujeto claro? | E12: ✓ Cumple
B13: 5 | C13: Adjetivos cuantificables | D13: ¿Los calificativos ('grande', 'muchos', 'suficiente') se expresan con números o rangos? | E13: ✓ Cumple
B14: AMBIGÜEDAD FUNCIONAL
B15: 6 | C15: Acción única y clara | D15: ¿La historia describe una sola capacidad? ¿Se evita el 'y/o' que oculta múltiples funciones? | E15: ✓ Cumple
B16: 7 | C16: Actor identificado | D16: ¿Está claro QUIÉN ejecuta la acción y quién se beneficia? | E16: ✓ Cumple
B17: 8 | C17: Comportamiento esperado | D17: ¿Se especifica el resultado observable de la acción (no solo la intención)? | E17: ✓ Cumple
B18: 9 | C18: Manejo de errores / excepciones | D18: ¿Se describen los caminos alternos y qué ocurre ante entradas inválidas? | E18: ✓ Cumple
B19: 10 | C19: Reglas de negocio explícitas | D19: ¿Las validaciones, cálculos y condiciones están declaradas y no supuestas? | E19: ✓ Cumple
B20: 11 | C20: Dependencias funcionales | D20: ¿Se identifican precondiciones o historias de las que depende? | E20: ✓ Cumple
B21: AMBIGÜEDAD TEMPORAL
B22: 12 | C22: Momento / disparador | D22: ¿Está claro CUÁNDO ocurre la acción (evento, condición o frecuencia)? | E22: ✓ Cumple
B23: 13 | C23: Orden y secuencia | D23: ¿Se define el orden de los pasos cuando importa la secuencia? | E23: ✓ Cumple
B24: 14 | C24: Plazos y tiempos de respuesta | D24: ¿Se cuantifican tiempos, timeouts, SLA o vigencias ('en X segundos', 'hasta las 23:59')? | E24: N/A
B25: 15 | C25: Estados y transiciones | D25: ¿Se describen los estados del objeto y las transiciones válidas entre ellos? | E25: N/A
B26: 16 | C26: Concurrencia / simultaneidad | D26: ¿Se contempla qué pasa si varios usuarios/procesos actúan a la vez? | E26: N/A
B27: AMBIGÜEDAD DE ALCANCE
B28: 17 | C28: Límites (in/out of scope) | D28: ¿Se declara explícitamente qué queda FUERA del alcance de la historia? | E28: ⚠ Revisar | F28: La historia no declara explícitamente qué queda fuera de su alcance. | G28: Agregar una sección 'Fuera de alcance' que indique explícitamente las funcionalidades excluidas.
B29: 18 | C29: Tamaño / granularidad (INVEST) | D29: ¿La historia es lo bastante pequeña para completarse en un sprint? ¿Es divisible? | E29: ✓ Cumple
B30: 19 | C30: Datos y volúmenes | D30: ¿Se acotan cantidades, límites de registros, formatos y rangos de datos? | E30: N/A
B31: 20 | C31: Roles y permisos afectados | D31: ¿Se delimita a qué perfiles/roles aplica y a cuáles no? | E31: ✓ Cumple
B32: 21 | C32: Plataformas / entornos | D32: ¿Se especifican dispositivos, navegadores, idiomas o entornos cubiertos? | E32: ⚠ Revisar | F32: No se especifican dispositivos, navegadores, resoluciones o idiomas soportados para esta funcionalidad. | G32: Definir explícitamente los entornos soportados (navegador de escritorio, resolución mínima, idioma único: español).
B33: 22 | C33: Criterios medibles / testables | D33: ¿Cada afirmación puede verificarse objetivamente con una prueba? | E33: ✓ Cumple
B35: Ítems 'No cumple' (críticos): | D35: =COUNTIF(E8:E33,"✗ No cumple") -> 0
B36: Ítems 'Revisar': | D36: =COUNTIF(E8:E33,"⚠ Revisar") -> 3
B37: VEREDICTO (Definition of Ready): | D37: =IF(D35>0,"RECHAZADA - corregir ambigüedades críticas",IF(D36>0,"APROBADA CON OBSERVACIONES - aclarar pendientes","APROBADA - lista para BDD")) -> APROBADA CON OBSERVACIONES - aclarar pendientes

Sheet CHK-US-007
B2: CHECKLIST DE DETECCIÓN DE AMBIGÜEDADES EN USER STORIES
B3: ID de la User Story: | D3: US-007 | E3: Evaluador: | G3: Anthony Joel Romero Yaguana
B4: Historia (Como <rol>, quiero <objetivo>, para <beneficio>):
B5: Como Analista de Triaje, quiero que el sistema detecte automáticamente casos duplicados o relacionados al registrar un nuevo caso, para evitar atención redundante y mantener consistencia en el seguimiento.
B7: # | C7: Aspecto a verificar | D7: Pregunta guía / criterio | E7: Estado | F7: Hallazgo detectado | G7: Reescritura sugerida
B8: AMBIGÜEDAD SEMÁNTICA
B9: 1 | C9: Términos vagos / subjetivos | D9: ¿Se evitan palabras como 'rápido', 'fácil', 'amigable', 'eficiente', 'intuitivo', 'óptimo' sin métrica? | E9: ✓ Cumple
B10: 2 | C10: Lenguaje ubicuo | D10: ¿Los términos del dominio están definidos en un glosario y se usan de forma consistente? | E10: ⚠ Revisar | F10: No se anexa un glosario formal de términos del dominio (caso, triaje, SLA, clasificación, confiabilidad, etc.); los términos se usan de forma consistente pero sin definición central. | G10: Anexar/referenciar un glosario de dominio compartido por todas las historias del backlog.
B11: 3 | C11: Sinónimos / homónimos | D11: ¿Un mismo concepto se nombra siempre igual? ¿Un término no tiene dos significados? | E11: ✓ Cumple
B12: 4 | C12: Pronombres sin referente | D12: ¿Se evita 'esto', 'eso', 'lo anterior' sin un sujeto claro? | E12: ✓ Cumple
B13: 5 | C13: Adjetivos cuantificables | D13: ¿Los calificativos ('grande', 'muchos', 'suficiente') se expresan con números o rangos? | E13: ✓ Cumple
B14: AMBIGÜEDAD FUNCIONAL
B15: 6 | C15: Acción única y clara | D15: ¿La historia describe una sola capacidad? ¿Se evita el 'y/o' que oculta múltiples funciones? | E15: ✓ Cumple
B16: 7 | C16: Actor identificado | D16: ¿Está claro QUIÉN ejecuta la acción y quién se beneficia? | E16: ✓ Cumple
B17: 8 | C17: Comportamiento esperado | D17: ¿Se especifica el resultado observable de la acción (no solo la intención)? | E17: ✓ Cumple
B18: 9 | C18: Manejo de errores / excepciones | D18: ¿Se describen los caminos alternos y qué ocurre ante entradas inválidas? | E18: ✓ Cumple
B19: 10 | C19: Reglas de negocio explícitas | D19: ¿Las validaciones, cálculos y condiciones están declaradas y no supuestas? | E19: ✓ Cumple
B20: 11 | C20: Dependencias funcionales | D20: ¿Se identifican precondiciones o historias de las que depende? | E20: ✓ Cumple
B21: AMBIGÜEDAD TEMPORAL
B22: 12 | C22: Momento / disparador | D22: ¿Está claro CUÁNDO ocurre la acción (evento, condición o frecuencia)? | E22: ✓ Cumple
B23: 13 | C23: Orden y secuencia | D23: ¿Se define el orden de los pasos cuando importa la secuencia? | E23: ✓ Cumple
B24: 14 | C24: Plazos y tiempos de respuesta | D24: ¿Se cuantifican tiempos, timeouts, SLA o vigencias ('en X segundos', 'hasta las 23:59')? | E24: ⚠ Revisar | F24: No se define un tiempo máximo para que el motor de detección calcule la similitud. | G24: Agregar un SLA de procesamiento del cálculo de similitud.
B25: 15 | C25: Estados y transiciones | D25: ¿Se describen los estados del objeto y las transiciones válidas entre ellos? | E25: N/A
B26: 16 | C26: Concurrencia / simultaneidad | D26: ¿Se contempla qué pasa si varios usuarios/procesos actúan a la vez? | E26: ⚠ Revisar | F26: No se define qué ocurre si se registran varios casos potencialmente duplicados entre sí de forma simultánea. | G26: Aclarar el comportamiento de detección ante registros concurrentes.
B27: AMBIGÜEDAD DE ALCANCE
B28: 17 | C28: Límites (in/out of scope) | D28: ¿Se declara explícitamente qué queda FUERA del alcance de la historia? | E28: ⚠ Revisar | F28: La historia no declara explícitamente qué queda fuera de su alcance. | G28: Agregar una sección 'Fuera de alcance' que indique explícitamente las funcionalidades excluidas.
B29: 18 | C29: Tamaño / granularidad (INVEST) | D29: ¿La historia es lo bastante pequeña para completarse en un sprint? ¿Es divisible? | E29: ⚠ Revisar | F29: Estimación de 8 puntos: evaluar si la historia es divisible (cálculo de similitud vs. presentación de alertas). | G29: Considerar dividir en historias más pequeñas.
B30: 19 | C30: Datos y volúmenes | D30: ¿Se acotan cantidades, límites de registros, formatos y rangos de datos? | E30: ⚠ Revisar | F30: Los umbrales de similitud se abstrajeron a 'umbral configurado'; los valores concretos (≥90% / 60-89%) solo aparecen en la Épica EP-03. | G30: Referenciar explícitamente los valores o el documento de configuración (EP-03) desde la propia historia.
B31: 20 | C31: Roles y permisos afectados | D31: ¿Se delimita a qué perfiles/roles aplica y a cuáles no? | E31: ✓ Cumple
B32: 21 | C32: Plataformas / entornos | D32: ¿Se especifican dispositivos, navegadores, idiomas o entornos cubiertos? | E32: ⚠ Revisar | F32: No se especifican dispositivos, navegadores, resoluciones o idiomas soportados para esta funcionalidad. | G32: Definir explícitamente los entornos soportados (navegador de escritorio, resolución mínima, idioma único: español).
B33: 22 | C33: Criterios medibles / testables | D33: ¿Cada afirmación puede verificarse objetivamente con una prueba? | E33: ✓ Cumple
B35: Ítems 'No cumple' (críticos): | D35: =COUNTIF(E8:E33,"✗ No cumple") -> 0
B36: Ítems 'Revisar': | D36: =COUNTIF(E8:E33,"⚠ Revisar") -> 7
B37: VEREDICTO (Definition of Ready): | D37: =IF(D35>0,"RECHAZADA - corregir ambigüedades críticas",IF(D36>0,"APROBADA CON OBSERVACIONES - aclarar pendientes","APROBADA - lista para BDD")) -> APROBADA CON OBSERVACIONES - aclarar pendientes

Sheet CHK-US-008
B2: CHECKLIST DE DETECCIÓN DE AMBIGÜEDADES EN USER STORIES
B3: ID de la User Story: | D3: US-008 | E3: Evaluador: | G3: Anthony Joel Romero Yaguana
B4: Historia (Como <rol>, quiero <objetivo>, para <beneficio>):
B5: Como Analista de Triaje, quiero derivar un caso ya clasificado al área o especialista responsable, para que continúe su proceso de resolución.
B7: # | C7: Aspecto a verificar | D7: Pregunta guía / criterio | E7: Estado | F7: Hallazgo detectado | G7: Reescritura sugerida
B8: AMBIGÜEDAD SEMÁNTICA
B9: 1 | C9: Términos vagos / subjetivos | D9: ¿Se evitan palabras como 'rápido', 'fácil', 'amigable', 'eficiente', 'intuitivo', 'óptimo' sin métrica? | E9: ✓ Cumple
B10: 2 | C10: Lenguaje ubicuo | D10: ¿Los términos del dominio están definidos en un glosario y se usan de forma consistente? | E10: ⚠ Revisar | F10: No se anexa un glosario formal de términos del dominio (caso, triaje, SLA, clasificación, confiabilidad, etc.); los términos se usan de forma consistente pero sin definición central. | G10: Anexar/referenciar un glosario de dominio compartido por todas las historias del backlog.
B11: 3 | C11: Sinónimos / homónimos | D11: ¿Un mismo concepto se nombra siempre igual? ¿Un término no tiene dos significados? | E11: ✓ Cumple
B12: 4 | C12: Pronombres sin referente | D12: ¿Se evita 'esto', 'eso', 'lo anterior' sin un sujeto claro? | E12: ✓ Cumple
B13: 5 | C13: Adjetivos cuantificables | D13: ¿Los calificativos ('grande', 'muchos', 'suficiente') se expresan con números o rangos? | E13: ✓ Cumple
B14: AMBIGÜEDAD FUNCIONAL
B15: 6 | C15: Acción única y clara | D15: ¿La historia describe una sola capacidad? ¿Se evita el 'y/o' que oculta múltiples funciones? | E15: ✓ Cumple
B16: 7 | C16: Actor identificado | D16: ¿Está claro QUIÉN ejecuta la acción y quién se beneficia? | E16: ✓ Cumple
B17: 8 | C17: Comportamiento esperado | D17: ¿Se especifica el resultado observable de la acción (no solo la intención)? | E17: ✓ Cumple
B18: 9 | C18: Manejo de errores / excepciones | D18: ¿Se describen los caminos alternos y qué ocurre ante entradas inválidas? | E18: ✓ Cumple
B19: 10 | C19: Reglas de negocio explícitas | D19: ¿Las validaciones, cálculos y condiciones están declaradas y no supuestas? | E19: ✓ Cumple
B20: 11 | C20: Dependencias funcionales | D20: ¿Se identifican precondiciones o historias de las que depende? | E20: ✓ Cumple
B21: AMBIGÜEDAD TEMPORAL
B22: 12 | C22: Momento / disparador | D22: ¿Está claro CUÁNDO ocurre la acción (evento, condición o frecuencia)? | E22: ✓ Cumple
B23: 13 | C23: Orden y secuencia | D23: ¿Se define el orden de los pasos cuando importa la secuencia? | E23: ✓ Cumple
B24: 14 | C24: Plazos y tiempos de respuesta | D24: ¿Se cuantifican tiempos, timeouts, SLA o vigencias ('en X segundos', 'hasta las 23:59')? | E24: N/A
B25: 15 | C25: Estados y transiciones | D25: ¿Se describen los estados del objeto y las transiciones válidas entre ellos? | E25: N/A
B26: 16 | C26: Concurrencia / simultaneidad | D26: ¿Se contempla qué pasa si varios usuarios/procesos actúan a la vez? | E26: ⚠ Revisar | F26: No se define qué ocurre si dos supervisores intentan derivar el mismo caso simultáneamente a áreas distintas. | G26: Agregar comportamiento ante derivación concurrente.
B27: AMBIGÜEDAD DE ALCANCE
B28: 17 | C28: Límites (in/out of scope) | D28: ¿Se declara explícitamente qué queda FUERA del alcance de la historia? | E28: ⚠ Revisar | F28: La historia no declara explícitamente qué queda fuera de su alcance. | G28: Agregar una sección 'Fuera de alcance' que indique explícitamente las funcionalidades excluidas.
B29: 18 | C29: Tamaño / granularidad (INVEST) | D29: ¿La historia es lo bastante pequeña para completarse en un sprint? ¿Es divisible? | E29: ✓ Cumple
B30: 19 | C30: Datos y volúmenes | D30: ¿Se acotan cantidades, límites de registros, formatos y rangos de datos? | E30: N/A
B31: 20 | C31: Roles y permisos afectados | D31: ¿Se delimita a qué perfiles/roles aplica y a cuáles no? | E31: ✓ Cumple
B32: 21 | C32: Plataformas / entornos | D32: ¿Se especifican dispositivos, navegadores, idiomas o entornos cubiertos? | E32: ⚠ Revisar | F32: No se especifican dispositivos, navegadores, resoluciones o idiomas soportados para esta funcionalidad. | G32: Definir explícitamente los entornos soportados (navegador de escritorio, resolución mínima, idioma único: español).
B33: 22 | C33: Criterios medibles / testables | D33: ¿Cada afirmación puede verificarse objetivamente con una prueba? | E33: ✓ Cumple
B35: Ítems 'No cumple' (críticos): | D35: =COUNTIF(E8:E33,"✗ No cumple") -> 0
B36: Ítems 'Revisar': | D36: =COUNTIF(E8:E33,"⚠ Revisar") -> 4
B37: VEREDICTO (Definition of Ready): | D37: =IF(D35>0,"RECHAZADA - corregir ambigüedades críticas",IF(D36>0,"APROBADA CON OBSERVACIONES - aclarar pendientes","APROBADA - lista para BDD")) -> APROBADA CON OBSERVACIONES - aclarar pendientes

Sheet CHK-US-009
B2: CHECKLIST DE DETECCIÓN DE AMBIGÜEDADES EN USER STORIES
B3: ID de la User Story: | D3: US-009 | E3: Evaluador: | G3: Anthony Joel Romero Yaguana
B4: Historia (Como <rol>, quiero <objetivo>, para <beneficio>):
B5: Como Supervisor Operativo, quiero cambiar el responsable asignado a un caso A&G activo registrando el motivo del cambio, para asegurar la continuidad de su gestión con respaldo auditable.
B7: # | C7: Aspecto a verificar | D7: Pregunta guía / criterio | E7: Estado | F7: Hallazgo detectado | G7: Reescritura sugerida
B8: AMBIGÜEDAD SEMÁNTICA
B9: 1 | C9: Términos vagos / subjetivos | D9: ¿Se evitan palabras como 'rápido', 'fácil', 'amigable', 'eficiente', 'intuitivo', 'óptimo' sin métrica? | E9: ✓ Cumple
B10: 2 | C10: Lenguaje ubicuo | D10: ¿Los términos del dominio están definidos en un glosario y se usan de forma consistente? | E10: ⚠ Revisar | F10: No se anexa un glosario formal de términos del dominio (caso, triaje, SLA, clasificación, confiabilidad, etc.); los términos se usan de forma consistente pero sin definición central. | G10: Anexar/referenciar un glosario de dominio compartido por todas las historias del backlog.
B11: 3 | C11: Sinónimos / homónimos | D11: ¿Un mismo concepto se nombra siempre igual? ¿Un término no tiene dos significados? | E11: ✓ Cumple
B12: 4 | C12: Pronombres sin referente | D12: ¿Se evita 'esto', 'eso', 'lo anterior' sin un sujeto claro? | E12: ✓ Cumple
B13: 5 | C13: Adjetivos cuantificables | D13: ¿Los calificativos ('grande', 'muchos', 'suficiente') se expresan con números o rangos? | E13: ✓ Cumple
B14: AMBIGÜEDAD FUNCIONAL
B15: 6 | C15: Acción única y clara | D15: ¿La historia describe una sola capacidad? ¿Se evita el 'y/o' que oculta múltiples funciones? | E15: ✓ Cumple
B16: 7 | C16: Actor identificado | D16: ¿Está claro QUIÉN ejecuta la acción y quién se beneficia? | E16: ✓ Cumple
B17: 8 | C17: Comportamiento esperado | D17: ¿Se especifica el resultado observable de la acción (no solo la intención)? | E17: ✓ Cumple
B18: 9 | C18: Manejo de errores / excepciones | D18: ¿Se describen los caminos alternos y qué ocurre ante entradas inválidas? | E18: ✓ Cumple
B19: 10 | C19: Reglas de negocio explícitas | D19: ¿Las validaciones, cálculos y condiciones están declaradas y no supuestas? | E19: ✓ Cumple
B20: 11 | C20: Dependencias funcionales | D20: ¿Se identifican precondiciones o historias de las que depende? | E20: ✓ Cumple
B21: AMBIGÜEDAD TEMPORAL
B22: 12 | C22: Momento / disparador | D22: ¿Está claro CUÁNDO ocurre la acción (evento, condición o frecuencia)? | E22: ✓ Cumple
B23: 13 | C23: Orden y secuencia | D23: ¿Se define el orden de los pasos cuando importa la secuencia? | E23: ✓ Cumple
B24: 14 | C24: Plazos y tiempos de respuesta | D24: ¿Se cuantifican tiempos, timeouts, SLA o vigencias ('en X segundos', 'hasta las 23:59')? | E24: N/A
B25: 15 | C25: Estados y transiciones | D25: ¿Se describen los estados del objeto y las transiciones válidas entre ellos? | E25: N/A
B26: 16 | C26: Concurrencia / simultaneidad | D26: ¿Se contempla qué pasa si varios usuarios/procesos actúan a la vez? | E26: ⚠ Revisar | F26: No se define qué ocurre si dos supervisores reasignan el mismo caso al mismo tiempo. | G26: Agregar: bloqueo o resolución de conflicto ante reasignación concurrente.
B27: AMBIGÜEDAD DE ALCANCE
B28: 17 | C28: Límites (in/out of scope) | D28: ¿Se declara explícitamente qué queda FUERA del alcance de la historia? | E28: ⚠ Revisar | F28: La historia no declara explícitamente qué queda fuera de su alcance. | G28: Agregar una sección 'Fuera de alcance' que indique explícitamente las funcionalidades excluidas.
B29: 18 | C29: Tamaño / granularidad (INVEST) | D29: ¿La historia es lo bastante pequeña para completarse en un sprint? ¿Es divisible? | E29: ✓ Cumple
B30: 19 | C30: Datos y volúmenes | D30: ¿Se acotan cantidades, límites de registros, formatos y rangos de datos? | E30: N/A
B31: 20 | C31: Roles y permisos afectados | D31: ¿Se delimita a qué perfiles/roles aplica y a cuáles no? | E31: ✓ Cumple
B32: 21 | C32: Plataformas / entornos | D32: ¿Se especifican dispositivos, navegadores, idiomas o entornos cubiertos? | E32: ⚠ Revisar | F32: No se especifican dispositivos, navegadores, resoluciones o idiomas soportados para esta funcionalidad. | G32: Definir explícitamente los entornos soportados (navegador de escritorio, resolución mínima, idioma único: español).
B33: 22 | C33: Criterios medibles / testables | D33: ¿Cada afirmación puede verificarse objetivamente con una prueba? | E33: ✓ Cumple
B35: Ítems 'No cumple' (críticos): | D35: =COUNTIF(E8:E33,"✗ No cumple") -> 0
B36: Ítems 'Revisar': | D36: =COUNTIF(E8:E33,"⚠ Revisar") -> 4
B37: VEREDICTO (Definition of Ready): | D37: =IF(D35>0,"RECHAZADA - corregir ambigüedades críticas",IF(D36>0,"APROBADA CON OBSERVACIONES - aclarar pendientes","APROBADA - lista para BDD")) -> APROBADA CON OBSERVACIONES - aclarar pendientes

Sheet CHK-US-010
B2: CHECKLIST DE DETECCIÓN DE AMBIGÜEDADES EN USER STORIES
B3: ID de la User Story: | D3: US-010 | E3: Evaluador: | G3: Anthony Joel Romero Yaguana
B4: Historia (Como <rol>, quiero <objetivo>, para <beneficio>):
B5: Como Supervisor Operativo, quiero visualizar el estado actual de los casos A&G, para dar seguimiento oportuno a la operación sin acceder a múltiples sistemas.
B7: # | C7: Aspecto a verificar | D7: Pregunta guía / criterio | E7: Estado | F7: Hallazgo detectado | G7: Reescritura sugerida
B8: AMBIGÜEDAD SEMÁNTICA
B9: 1 | C9: Términos vagos / subjetivos | D9: ¿Se evitan palabras como 'rápido', 'fácil', 'amigable', 'eficiente', 'intuitivo', 'óptimo' sin métrica? | E9: ✓ Cumple
B10: 2 | C10: Lenguaje ubicuo | D10: ¿Los términos del dominio están definidos en un glosario y se usan de forma consistente? | E10: ⚠ Revisar | F10: No se anexa un glosario formal de términos del dominio (caso, triaje, SLA, clasificación, confiabilidad, etc.); los términos se usan de forma consistente pero sin definición central. | G10: Anexar/referenciar un glosario de dominio compartido por todas las historias del backlog.
B11: 3 | C11: Sinónimos / homónimos | D11: ¿Un mismo concepto se nombra siempre igual? ¿Un término no tiene dos significados? | E11: ✓ Cumple
B12: 4 | C12: Pronombres sin referente | D12: ¿Se evita 'esto', 'eso', 'lo anterior' sin un sujeto claro? | E12: ✓ Cumple
B13: 5 | C13: Adjetivos cuantificables | D13: ¿Los calificativos ('grande', 'muchos', 'suficiente') se expresan con números o rangos? | E13: ✓ Cumple
B14: AMBIGÜEDAD FUNCIONAL
B15: 6 | C15: Acción única y clara | D15: ¿La historia describe una sola capacidad? ¿Se evita el 'y/o' que oculta múltiples funciones? | E15: ✓ Cumple
B16: 7 | C16: Actor identificado | D16: ¿Está claro QUIÉN ejecuta la acción y quién se beneficia? | E16: ✓ Cumple
B17: 8 | C17: Comportamiento esperado | D17: ¿Se especifica el resultado observable de la acción (no solo la intención)? | E17: ✓ Cumple
B18: 9 | C18: Manejo de errores / excepciones | D18: ¿Se describen los caminos alternos y qué ocurre ante entradas inválidas? | E18: ✓ Cumple
B19: 10 | C19: Reglas de negocio explícitas | D19: ¿Las validaciones, cálculos y condiciones están declaradas y no supuestas? | E19: ✓ Cumple
B20: 11 | C20: Dependencias funcionales | D20: ¿Se identifican precondiciones o historias de las que depende? | E20: ✓ Cumple
B21: AMBIGÜEDAD TEMPORAL
B22: 12 | C22: Momento / disparador | D22: ¿Está claro CUÁNDO ocurre la acción (evento, condición o frecuencia)? | E22: ✓ Cumple
B23: 13 | C23: Orden y secuencia | D23: ¿Se define el orden de los pasos cuando importa la secuencia? | E23: ✓ Cumple
B24: 14 | C24: Plazos y tiempos de respuesta | D24: ¿Se cuantifican tiempos, timeouts, SLA o vigencias ('en X segundos', 'hasta las 23:59')? | E24: N/A
B25: 15 | C25: Estados y transiciones | D25: ¿Se describen los estados del objeto y las transiciones válidas entre ellos? | E25: ✓ Cumple
B26: 16 | C26: Concurrencia / simultaneidad | D26: ¿Se contempla qué pasa si varios usuarios/procesos actúan a la vez? | E26: N/A
B27: AMBIGÜEDAD DE ALCANCE
B28: 17 | C28: Límites (in/out of scope) | D28: ¿Se declara explícitamente qué queda FUERA del alcance de la historia? | E28: ⚠ Revisar | F28: La historia no declara explícitamente qué queda fuera de su alcance. | G28: Agregar una sección 'Fuera de alcance' que indique explícitamente las funcionalidades excluidas.
B29: 18 | C29: Tamaño / granularidad (INVEST) | D29: ¿La historia es lo bastante pequeña para completarse en un sprint? ¿Es divisible? | E29: ✓ Cumple
B30: 19 | C30: Datos y volúmenes | D30: ¿Se acotan cantidades, límites de registros, formatos y rangos de datos? | E30: N/A
B31: 20 | C31: Roles y permisos afectados | D31: ¿Se delimita a qué perfiles/roles aplica y a cuáles no? | E31: ✓ Cumple
B32: 21 | C32: Plataformas / entornos | D32: ¿Se especifican dispositivos, navegadores, idiomas o entornos cubiertos? | E32: ⚠ Revisar | F32: No se especifican dispositivos, navegadores, resoluciones o idiomas soportados para esta funcionalidad. | G32: Definir explícitamente los entornos soportados (navegador de escritorio, resolución mínima, idioma único: español).
B33: 22 | C33: Criterios medibles / testables | D33: ¿Cada afirmación puede verificarse objetivamente con una prueba? | E33: ✓ Cumple
B35: Ítems 'No cumple' (críticos): | D35: =COUNTIF(E8:E33,"✗ No cumple") -> 0
B36: Ítems 'Revisar': | D36: =COUNTIF(E8:E33,"⚠ Revisar") -> 3
B37: VEREDICTO (Definition of Ready): | D37: =IF(D35>0,"RECHAZADA - corregir ambigüedades críticas",IF(D36>0,"APROBADA CON OBSERVACIONES - aclarar pendientes","APROBADA - lista para BDD")) -> APROBADA CON OBSERVACIONES - aclarar pendientes

Sheet CHK-US-011
B2: CHECKLIST DE DETECCIÓN DE AMBIGÜEDADES EN USER STORIES
B3: ID de la User Story: | D3: US-011 | E3: Evaluador: | G3: Anthony Joel Romero Yaguana
B4: Historia (Como <rol>, quiero <objetivo>, para <beneficio>):
B5: Como Supervisor Operativo, quiero acceder a un tablero consolidado con indicadores operativos y alertas de SLA, para tener visibilidad global del desempeño del equipo de triaje.
B7: # | C7: Aspecto a verificar | D7: Pregunta guía / criterio | E7: Estado | F7: Hallazgo detectado | G7: Reescritura sugerida
B8: AMBIGÜEDAD SEMÁNTICA
B9: 1 | C9: Términos vagos / subjetivos | D9: ¿Se evitan palabras como 'rápido', 'fácil', 'amigable', 'eficiente', 'intuitivo', 'óptimo' sin métrica? | E9: ✓ Cumple
B10: 2 | C10: Lenguaje ubicuo | D10: ¿Los términos del dominio están definidos en un glosario y se usan de forma consistente? | E10: ⚠ Revisar | F10: No se anexa un glosario formal de términos del dominio (caso, triaje, SLA, clasificación, confiabilidad, etc.); los términos se usan de forma consistente pero sin definición central. | G10: Anexar/referenciar un glosario de dominio compartido por todas las historias del backlog.
B11: 3 | C11: Sinónimos / homónimos | D11: ¿Un mismo concepto se nombra siempre igual? ¿Un término no tiene dos significados? | E11: ✓ Cumple
B12: 4 | C12: Pronombres sin referente | D12: ¿Se evita 'esto', 'eso', 'lo anterior' sin un sujeto claro? | E12: ✓ Cumple
B13: 5 | C13: Adjetivos cuantificables | D13: ¿Los calificativos ('grande', 'muchos', 'suficiente') se expresan con números o rangos? | E13: ✓ Cumple
B14: AMBIGÜEDAD FUNCIONAL
B15: 6 | C15: Acción única y clara | D15: ¿La historia describe una sola capacidad? ¿Se evita el 'y/o' que oculta múltiples funciones? | E15: ✓ Cumple
B16: 7 | C16: Actor identificado | D16: ¿Está claro QUIÉN ejecuta la acción y quién se beneficia? | E16: ✓ Cumple
B17: 8 | C17: Comportamiento esperado | D17: ¿Se especifica el resultado observable de la acción (no solo la intención)? | E17: ✓ Cumple
B18: 9 | C18: Manejo de errores / excepciones | D18: ¿Se describen los caminos alternos y qué ocurre ante entradas inválidas? | E18: ⚠ Revisar | F18: No se describe qué ocurre si no hay datos suficientes para calcular los indicadores (p. ej. periodo sin casos). | G18: Agregar: 'Dado que no existen casos en el periodo consultado, entonces el sistema muestra el tablero con indicadores en cero y un mensaje informativo.'
B19: 10 | C19: Reglas de negocio explícitas | D19: ¿Las validaciones, cálculos y condiciones están declaradas y no supuestas? | E19: ✓ Cumple
B20: 11 | C20: Dependencias funcionales | D20: ¿Se identifican precondiciones o historias de las que depende? | E20: ✓ Cumple
B21: AMBIGÜEDAD TEMPORAL
B22: 12 | C22: Momento / disparador | D22: ¿Está claro CUÁNDO ocurre la acción (evento, condición o frecuencia)? | E22: ✓ Cumple
B23: 13 | C23: Orden y secuencia | D23: ¿Se define el orden de los pasos cuando importa la secuencia? | E23: ✓ Cumple
B24: 14 | C24: Plazos y tiempos de respuesta | D24: ¿Se cuantifican tiempos, timeouts, SLA o vigencias ('en X segundos', 'hasta las 23:59')? | E24: N/A
B25: 15 | C25: Estados y transiciones | D25: ¿Se describen los estados del objeto y las transiciones válidas entre ellos? | E25: N/A
B26: 16 | C26: Concurrencia / simultaneidad | D26: ¿Se contempla qué pasa si varios usuarios/procesos actúan a la vez? | E26: N/A
B27: AMBIGÜEDAD DE ALCANCE
B28: 17 | C28: Límites (in/out of scope) | D28: ¿Se declara explícitamente qué queda FUERA del alcance de la historia? | E28: ⚠ Revisar | F28: La historia no declara explícitamente qué queda fuera de su alcance. | G28: Agregar una sección 'Fuera de alcance' que indique explícitamente las funcionalidades excluidas.
B29: 18 | C29: Tamaño / granularidad (INVEST) | D29: ¿La historia es lo bastante pequeña para completarse en un sprint? ¿Es divisible? | E29: ✓ Cumple
B30: 19 | C30: Datos y volúmenes | D30: ¿Se acotan cantidades, límites de registros, formatos y rangos de datos? | E30: ⚠ Revisar | F30: El riesgo asociado menciona picos de demanda del 20% pero el criterio de aceptación no acota el volumen de datos que el tablero debe soportar. | G30: Cuantificar el volumen máximo de casos/eventos que el tablero debe procesar sin degradar el tiempo de carga.
B31: 20 | C31: Roles y permisos afectados | D31: ¿Se delimita a qué perfiles/roles aplica y a cuáles no? | E31: ✓ Cumple
B32: 21 | C32: Plataformas / entornos | D32: ¿Se especifican dispositivos, navegadores, idiomas o entornos cubiertos? | E32: ⚠ Revisar | F32: No se especifican dispositivos, navegadores, resoluciones o idiomas soportados para esta funcionalidad. | G32: Definir explícitamente los entornos soportados (navegador de escritorio, resolución mínima, idioma único: español).
B33: 22 | C33: Criterios medibles / testables | D33: ¿Cada afirmación puede verificarse objetivamente con una prueba? | E33: ✓ Cumple
B35: Ítems 'No cumple' (críticos): | D35: =COUNTIF(E8:E33,"✗ No cumple") -> 0
B36: Ítems 'Revisar': | D36: =COUNTIF(E8:E33,"⚠ Revisar") -> 5
